<?xml version="1.0"?>

<robot name="robot_diff" xmlns:xacro="http://ros.org/wiki/xacro">
    <link name="base_link">

    </link>

<!--ROBOT CHASSI AND OTHER --> 

    <link name="chassi">
        <visual>
            <origin xyz="0.0 0.0 0.0" rpy="0.0 0.0 0.0"/>
            <geometry>
                <mesh filename="package://gazebo_urdf/meshes/Robot.dae"/>
            </geometry>            
        </visual>
        <collision>
            <origin xyz="0.0 0.0 0.0" rpy="0.0 0.0 0.0"/>
            <geometry>
                <mesh filename="package://gazebo_urdf/meshes/Robot.dae"/>
            </geometry>
        </collision>
        <inertial>
            <origin xyz="0.0 0.0 0.0" rpy="0.0 0.0 0.0"/>
            <mass value="0.049269"/>
            <inertia ixx="1.14596769e-4" ixy="-5.431e-11" ixz="-1.451e-11" iyy="2.653e-5" iyz="4.381e-6" izz="1.372e-4"/>
        </inertial>
    </link>
    <joint name="base_to_chassi" type="fixed">
        <origin xyz="0.0 0.0 0.0" rpy="0.0 0.0 0.0"/>
        <parent link="base_link"/>
        <child link="chassi"/>
        <axis xyz="0.0 1.0 0.0"/>
    </joint>  


<!--LEFT WHEEL-->

    <link name="left_wheel">
        <visual>
            <origin xyz="0.0 0.0 0.0" rpy="0.0 0.0 0.0"/>
            <geometry>
                <mesh filename="package://gazebo_urdf/meshes/Roue_65mm.dae"/>
            </geometry>
        </visual>
        <collision>
            <origin xyz="0.0 0.0 0.0" rpy="0.0 0.0 0.0"/>
            <geometry>
                <mesh filename="package://gazebo_urdf/meshes/Roue_65mm.dae"/>
            </geometry>
        </collision>
        <inertial>
            <origin xyz="0.0 0.0 0.0" rpy="0.0 0.0 0.0"/>
            <mass value="0.025"/>
            <inertia ixx="1.564e-5" ixy="1.38055957e-15" ixz="3.31600822e-15" iyy="9.66657107e-6" iyz="-1.38581057e-15" izz="9.66701021e-6"/>
        </inertial>
    </link>

    <joint name="base_to_left_wheel" type="continuous">
        <origin xyz="0.048790 0.019314 -0.015708" rpy="0.0 0.0 0.0"/>
        <parent link="chassi"/>
        <child link="left_wheel"/>
        <axis xyz="1.0 0.0 0.0"/> <!--indicate the wheel will rotate in x axis-->
    </joint>

    <transmission name="trans_left_wheel">
        <type>transmission_interface/SimpleTransmission</type>
        <joint name="base_to_left_wheel">
            <hardwareInterface>hardware_interface/VelocityJointInterface</hardwareInterface>
        </joint>
        <actuator name="left_wheel_motor">
            <mechanicalReduction>1</mechanicalReduction>
        </actuator>
	</transmission>



<!--RIGHT WHEEL-->


    <link name="right_wheel">
        <visual>
            <origin xyz="0.0 0.0 0.0" rpy="0.0 0.0 3.14"/>
            <geometry>
                <mesh filename="package://gazebo_urdf/meshes/Roue_65mm.dae"/>
            </geometry>
        </visual>
        <collision>
            <origin xyz="0.0 0.0 0.0" rpy="0.0 0.0 3.14"/>
            <geometry>
                <mesh filename="package://gazebo_urdf/meshes/Roue_65mm.dae"/>
            </geometry>
        </collision>
        <inertial>
            <origin xyz="0.0 0.0 0.0" rpy="0.0 0.0 3.14"/>
            <mass value="0.025"/>
            <inertia ixx="1.564e-5" ixy="1.38055957e-15" ixz="3.31600822e-15" iyy="9.66657107e-6" iyz="-1.38581057e-15" izz="9.66701021e-6"/>
        </inertial>
    </link>

    <joint name="base_to_right_wheel" type="continuous">
        <origin xyz="-0.048332 0.021179 -0.015706" rpy="0.0 0.0 0.0"/>
        <parent link="chassi"/>
        <child link="right_wheel"/>
        <axis xyz="1.0 0.0 0.0"/>  <!--indicate the wheel will rotate in x axis-->
    </joint>

    <transmission name="trans_right_wheel">
        <type>transmission_interface/SimpleTransmission</type>
        <joint name="base_to_right_wheel">
            <hardwareInterface>hardware_interface/VelocityJointInterface</hardwareInterface>
        </joint>
        <actuator name="right_wheel_motor">
            <mechanicalReduction>1</mechanicalReduction>
        </actuator>
	</transmission>

<!--PIVOT-->

    <link name="pivot">                                                                                                                                         
        <visual>                                                                    
            <origin xyz="0 0 0" rpy="3.14 0 0" />                                                   
            <geometry>                                                                   
                <mesh filename="package://gazebo_urdf/meshes/pivot.dae" />     
            </geometry>                                                                   
        </visual>                                                                   
        <collision>                                                                   
            <origin xyz="0 0 0" rpy="3.14 0 0" />                                                    
            <geometry>                                                                   
                <mesh filename="package://gazebo_urdf/meshes/pivot.dae" />     
            </geometry>                                                                   
        </collision>                                                                    
        <inertial>                                                                    
            <origin xyz="0 0 0" rpy="3.14 0 0"/>                                                                   
            <mass value="0.011"/>                                                                   
            <inertia ixx="1.812e-6"  ixy="-1.199e-11"  ixz="-4.448e-9" iyy="1.783e-6" iyz="-1.755e-9" izz="9.698e-7" />                                                                   
        </inertial>                                                                   
    </link>                                  

    <joint name="pivot_to_chassi" type="fixed">
        <parent link="chassi"/>
        <child link="pivot"/>
        <origin xyz="-0.01500 -0.05000 -0.039500" rpy="0 0 0" />
        <axis xyz="0.0 0.0 0.0"/> 
    </joint>

<!--PIVOT_WHEEL-->

    <link name="pivot_wheel">                                                                                                                                         
        <visual>                                                                    
            <origin xyz="0 0 0" rpy="0 0 0" />                                                   
            <geometry>                                                                   
                <mesh filename="package://gazebo_urdf/meshes/ball.dae"/>     
            </geometry>                                                                   
        </visual>                                                                   
        <collision>                                                                   
            <origin xyz="0 0 0" rpy="0 0 0" />                                                    
            <geometry>                                                                   
                <mesh filename="package://gazebo_urdf/meshes/ball.dae" />     
            </geometry>                                                                   
        </collision>                                                                    
        <inertial>                                                                    
            <origin xyz="0 0 0" rpy="0 0 0"/>                                                                   
            <mass value="0.002"/>                                                                   
            <inertia ixx="8.024e-8"  ixy="0.000e+0"  ixz="0.000e+0" iyy="8.024e-8" iyz="1.949e-16" izz="8.320e-8"/>                                                                   
        </inertial>                                                                   
    </link>                                                                   

    <joint name="pivot_to_wheel" type="continuous">
        <parent link="pivot"/>
        <child link="pivot_wheel"/>
        <origin xyz="0.013 0.006 -0.010000" rpy="0 0 0" />
        <axis xyz="1 1 0" />
    </joint>

</robot>