<?xml version="1.0"?>

<robot name="robot_diff" xmlns:xacro="http://ros.org/wiki/xacro">
    <link name="base_link">

    </link>

<!--ROBOT CHASSI AND OTHER --> 

    <link name="chassi">
        <visual>
            <origin xyz="0.0 0.0 0.0" rpy="0.0 0.0 0.0"/>
            <geometry>
                <mesh filename="package://gazebo_urdf/meshes/Robot.dae"/>
            </geometry>            
        </visual>
        <collision>
            <origin xyz="0.0 0.0 0.0" rpy="0.0 0.0 0.0"/>
            <geometry>
                <mesh filename="package://gazebo_urdf/meshes/Robot.dae"/>
            </geometry>
        </collision>
        <inertial>
            <origin xyz="0.0 0.0 0.0" rpy="0.0 0.0 0.0"/>
            <mass value="0.0"/>
            <inertia ixx="0.0" ixy="0.0" ixz="0.0" iyy="0.0" iyz="0.0" izz="0.0"/>
        </inertial>
    </link>
    <joint name="base_to_chassi" type="fixed">
        <origin xyz="0.0 0.0 0.0" rpy="0.0 0.0 0.0"/>
        <parent link="base_link"/>
        <child link="chassi"/>
    </joint>  


<!--LEFT WHEEL-->

    <link name="left_wheel">
        <visual>
            <origin xyz="0.0 0.0 0.0" rpy="0.0 0.0 0.0"/>
            <geometry>
                <mesh filename="package://gazebo_urdf/meshes/Roue_65mm.dae"/>
            </geometry>
        </visual>
        <collision>
            <origin xyz="0.0 0.0 0.0" rpy="0.0 0.0 0.0"/>
            <geometry>
                <mesh filename="package://gazebo_urdf/meshes/Roue_65mm.dae"/>
            </geometry>
        </collision>
        <inertial>
            <origin xyz="0.0 0.0 0.0" rpy="0.0 0.0 0.0"/>
            <mass value="0.0"/>
            <inertia ixx="0.0" ixy="0.0" ixz="0.0" iyy="0.0" iyz="0.0" izz="0.0"/>
        </inertial>
    </link>
    <joint name="base_to_left_wheel" type="continuous">
        <origin xyz="0.048790 0.019314 -0.015708" rpy="0.0 0.0 0.0"/>
        <parent link="chassi"/>
        <child link="left_wheel"/>
        <axis xyz="0.0 1.0 0.0"/>
    </joint>



<!--RIGHT WHEEL-->


    <link name="right_wheel">
        <visual>
            <origin xyz="0.0 0.0 0.0" rpy="0.0 0.0 3.14"/>
            <geometry>
                <mesh filename="package://gazebo_urdf/meshes/Roue_65mm.dae"/>
            </geometry>
        </visual>
        <collision>
            <origin xyz="0.0 0.0 0.0" rpy="0.0 0.0 3.14"/>
            <geometry>
                <mesh filename="package://gazebo_urdf/meshes/Roue_65mm.dae"/>
            </geometry>
        </collision>
        <inertial>
            <origin xyz="0.0 0.0 0.0" rpy="0.0 0.0 3.14"/>
            <mass value="0.0"/>
            <inertia ixx="0.0" ixy="0.0" ixz="0.0" iyy="0.0" iyz="0.0" izz="0.0"/>
        </inertial>
    </link>
    <joint name="base_to_right_wheel" type="continuous">
        <origin xyz="-0.048332 0.021179 -0.015706" rpy="0.0 0.0 0.0"/>
        <parent link="chassi"/>
        <child link="right_wheel"/>
        <axis xyz="0.0 1.0 0.0"/>
    </joint>
</robot>